[2023-09-06 16:05:04,537] INFO 127.0.0.1 - - [06/Sep/2023 16:05:04] "GET /openapi/swagger HTTP/1.1" 200 - - call_trace=C:\Users\thymont\OneDrive\Documentos\Engenharia de software\mvp-3-card-game-backend\app\venv\Lib\site-packages\werkzeug\_internal.py L187 
[2023-09-06 16:05:04,579] INFO 127.0.0.1 - - [06/Sep/2023 16:05:04] "[36mGET /openapi/static/css/swagger-ui.css HTTP/1.1[0m" 304 - - call_trace=C:\Users\thymont\OneDrive\Documentos\Engenharia de software\mvp-3-card-game-backend\app\venv\Lib\site-packages\werkzeug\_internal.py L187 
[2023-09-06 16:05:04,593] INFO 127.0.0.1 - - [06/Sep/2023 16:05:04] "[36mGET /openapi/static/js/swagger-ui-standalone-preset.js HTTP/1.1[0m" 304 - - call_trace=C:\Users\thymont\OneDrive\Documentos\Engenharia de software\mvp-3-card-game-backend\app\venv\Lib\site-packages\werkzeug\_internal.py L187 
[2023-09-06 16:05:04,594] INFO 127.0.0.1 - - [06/Sep/2023 16:05:04] "[36mGET /openapi/static/js/swagger-ui-bundle.js HTTP/1.1[0m" 304 - - call_trace=C:\Users\thymont\OneDrive\Documentos\Engenharia de software\mvp-3-card-game-backend\app\venv\Lib\site-packages\werkzeug\_internal.py L187 
[2023-09-06 16:05:04,740] INFO 127.0.0.1 - - [06/Sep/2023 16:05:04] "GET /openapi/openapi.json HTTP/1.1" 200 - - call_trace=C:\Users\thymont\OneDrive\Documentos\Engenharia de software\mvp-3-card-game-backend\app\venv\Lib\site-packages\werkzeug\_internal.py L187 
[2023-09-06 16:05:04,747] INFO 127.0.0.1 - - [06/Sep/2023 16:05:04] "[36mGET /openapi/static/images/swagger.svg HTTP/1.1[0m" 304 - - call_trace=C:\Users\thymont\OneDrive\Documentos\Engenharia de software\mvp-3-card-game-backend\app\venv\Lib\site-packages\werkzeug\_internal.py L187 
[2023-09-06 16:05:51,958] ERROR Exception on /updatecoins [PUT] - call_trace=C:\Users\thymont\OneDrive\Documentos\Engenharia de software\mvp-3-card-game-backend\app\venv\Lib\site-packages\flask\app.py L1414
Traceback (most recent call last):
  File "C:\Users\thymont\OneDrive\Documentos\Engenharia de software\mvp-3-card-game-backend\app\venv\Lib\site-packages\flask\app.py", line 2190, in wsgi_app
    response = self.full_dispatch_request()
               ^^^^^^^^^^^^^^^^^^^^^^^^^^^^
  File "C:\Users\thymont\OneDrive\Documentos\Engenharia de software\mvp-3-card-game-backend\app\venv\Lib\site-packages\flask\app.py", line 1486, in full_dispatch_request
    rv = self.handle_user_exception(e)
         ^^^^^^^^^^^^^^^^^^^^^^^^^^^^^
  File "C:\Users\thymont\OneDrive\Documentos\Engenharia de software\mvp-3-card-game-backend\app\venv\Lib\site-packages\flask_cors\extension.py", line 176, in wrapped_function
    return cors_after_request(app.make_response(f(*args, **kwargs)))
                                                ^^^^^^^^^^^^^^^^^^
  File "C:\Users\thymont\OneDrive\Documentos\Engenharia de software\mvp-3-card-game-backend\app\venv\Lib\site-packages\flask\app.py", line 1484, in full_dispatch_request
    rv = self.dispatch_request()
         ^^^^^^^^^^^^^^^^^^^^^^^
  File "C:\Users\thymont\OneDrive\Documentos\Engenharia de software\mvp-3-card-game-backend\app\venv\Lib\site-packages\flask\app.py", line 1469, in dispatch_request
    return self.ensure_sync(self.view_functions[rule.endpoint])(**view_args)
           ^^^^^^^^^^^^^^^^^^^^^^^^^^^^^^^^^^^^^^^^^^^^^^^^^^^^^^^^^^^^^^^^^
  File "C:\Users\thymont\OneDrive\Documentos\Engenharia de software\mvp-3-card-game-backend\app\venv\Lib\site-packages\flask_openapi3\scaffold.py", line 127, in view_func
    response = func(**func_kwargs)
               ^^^^^^^^^^^^^^^^^^^
  File "C:\Users\thymont\OneDrive\Documentos\Engenharia de software\mvp-3-card-game-backend\app\app.py", line 66, in update_wallet
    return service.update_wallet(form)
           ^^^^^^^^^^^^^^^^^^^^^^^^^^^
  File "C:\Users\thymont\OneDrive\Documentos\Engenharia de software\mvp-3-card-game-backend\app\service\player_service.py", line 94, in update_wallet
    Player.id == form.id).first()
                 ^^^^^^^
AttributeError: 'UpdateWalletForm' object has no attribute 'id'
[2023-09-06 16:05:51,965] INFO 127.0.0.1 - - [06/Sep/2023 16:05:51] "[35m[1mPUT /updatecoins HTTP/1.1[0m" 500 - - call_trace=C:\Users\thymont\OneDrive\Documentos\Engenharia de software\mvp-3-card-game-backend\app\venv\Lib\site-packages\werkzeug\_internal.py L187 
[2023-09-06 16:08:54,945] ERROR Exception on /updatecoins [PUT] - call_trace=C:\Users\thymont\OneDrive\Documentos\Engenharia de software\mvp-3-card-game-backend\app\venv\Lib\site-packages\flask\app.py L1414
Traceback (most recent call last):
  File "C:\Users\thymont\OneDrive\Documentos\Engenharia de software\mvp-3-card-game-backend\app\venv\Lib\site-packages\flask\app.py", line 2190, in wsgi_app
    response = self.full_dispatch_request()
               ^^^^^^^^^^^^^^^^^^^^^^^^^^^^
  File "C:\Users\thymont\OneDrive\Documentos\Engenharia de software\mvp-3-card-game-backend\app\venv\Lib\site-packages\flask\app.py", line 1486, in full_dispatch_request
    rv = self.handle_user_exception(e)
         ^^^^^^^^^^^^^^^^^^^^^^^^^^^^^
  File "C:\Users\thymont\OneDrive\Documentos\Engenharia de software\mvp-3-card-game-backend\app\venv\Lib\site-packages\flask_cors\extension.py", line 176, in wrapped_function
    return cors_after_request(app.make_response(f(*args, **kwargs)))
                                                ^^^^^^^^^^^^^^^^^^
  File "C:\Users\thymont\OneDrive\Documentos\Engenharia de software\mvp-3-card-game-backend\app\venv\Lib\site-packages\flask\app.py", line 1484, in full_dispatch_request
    rv = self.dispatch_request()
         ^^^^^^^^^^^^^^^^^^^^^^^
  File "C:\Users\thymont\OneDrive\Documentos\Engenharia de software\mvp-3-card-game-backend\app\venv\Lib\site-packages\flask\app.py", line 1469, in dispatch_request
    return self.ensure_sync(self.view_functions[rule.endpoint])(**view_args)
           ^^^^^^^^^^^^^^^^^^^^^^^^^^^^^^^^^^^^^^^^^^^^^^^^^^^^^^^^^^^^^^^^^
  File "C:\Users\thymont\OneDrive\Documentos\Engenharia de software\mvp-3-card-game-backend\app\venv\Lib\site-packages\flask_openapi3\scaffold.py", line 127, in view_func
    response = func(**func_kwargs)
               ^^^^^^^^^^^^^^^^^^^
  File "C:\Users\thymont\OneDrive\Documentos\Engenharia de software\mvp-3-card-game-backend\app\app.py", line 66, in update_wallet
    return service.update_wallet(form)
           ^^^^^^^^^^^^^^^^^^^^^^^^^^^
  File "C:\Users\thymont\OneDrive\Documentos\Engenharia de software\mvp-3-card-game-backend\app\service\player_service.py", line 94, in update_wallet
    Player.id == form.id).first()
                 ^^^^^^^
AttributeError: 'UpdateWalletForm' object has no attribute 'id'
[2023-09-06 16:08:54,951] INFO 127.0.0.1 - - [06/Sep/2023 16:08:54] "[35m[1mPUT /updatecoins HTTP/1.1[0m" 500 - - call_trace=C:\Users\thymont\OneDrive\Documentos\Engenharia de software\mvp-3-card-game-backend\app\venv\Lib\site-packages\werkzeug\_internal.py L187 
[2023-09-06 16:16:14,368] INFO [31m[1mWARNING: This is a development server. Do not use it in a production deployment. Use a production WSGI server instead.[0m
 * Running on all addresses (0.0.0.0)
 * Running on http://127.0.0.1:5000
 * Running on http://192.168.1.12:5000 - call_trace=C:\Users\thymont\OneDrive\Documentos\Engenharia de software\mvp-3-card-game-backend\app\venv\Lib\site-packages\werkzeug\_internal.py L187 
[2023-09-06 16:16:14,369] INFO [33mPress CTRL+C to quit[0m - call_trace=C:\Users\thymont\OneDrive\Documentos\Engenharia de software\mvp-3-card-game-backend\app\venv\Lib\site-packages\werkzeug\_internal.py L187 
[2023-09-06 16:16:21,867] ERROR Exception on /updatecoins [PUT] - call_trace=C:\Users\thymont\OneDrive\Documentos\Engenharia de software\mvp-3-card-game-backend\app\venv\Lib\site-packages\flask\app.py L1414
Traceback (most recent call last):
  File "C:\Users\thymont\OneDrive\Documentos\Engenharia de software\mvp-3-card-game-backend\app\venv\Lib\site-packages\flask\app.py", line 2190, in wsgi_app
    response = self.full_dispatch_request()
               ^^^^^^^^^^^^^^^^^^^^^^^^^^^^
  File "C:\Users\thymont\OneDrive\Documentos\Engenharia de software\mvp-3-card-game-backend\app\venv\Lib\site-packages\flask\app.py", line 1486, in full_dispatch_request
    rv = self.handle_user_exception(e)
         ^^^^^^^^^^^^^^^^^^^^^^^^^^^^^
  File "C:\Users\thymont\OneDrive\Documentos\Engenharia de software\mvp-3-card-game-backend\app\venv\Lib\site-packages\flask_cors\extension.py", line 176, in wrapped_function
    return cors_after_request(app.make_response(f(*args, **kwargs)))
                                                ^^^^^^^^^^^^^^^^^^
  File "C:\Users\thymont\OneDrive\Documentos\Engenharia de software\mvp-3-card-game-backend\app\venv\Lib\site-packages\flask\app.py", line 1484, in full_dispatch_request
    rv = self.dispatch_request()
         ^^^^^^^^^^^^^^^^^^^^^^^
  File "C:\Users\thymont\OneDrive\Documentos\Engenharia de software\mvp-3-card-game-backend\app\venv\Lib\site-packages\flask\app.py", line 1469, in dispatch_request
    return self.ensure_sync(self.view_functions[rule.endpoint])(**view_args)
           ^^^^^^^^^^^^^^^^^^^^^^^^^^^^^^^^^^^^^^^^^^^^^^^^^^^^^^^^^^^^^^^^^
  File "C:\Users\thymont\OneDrive\Documentos\Engenharia de software\mvp-3-card-game-backend\app\venv\Lib\site-packages\flask_openapi3\scaffold.py", line 127, in view_func
    response = func(**func_kwargs)
               ^^^^^^^^^^^^^^^^^^^
  File "C:\Users\thymont\OneDrive\Documentos\Engenharia de software\mvp-3-card-game-backend\app\app.py", line 66, in update_wallet
    return service.update_wallet(form)
           ^^^^^^^^^^^^^^^^^^^^^^^^^^^
  File "C:\Users\thymont\OneDrive\Documentos\Engenharia de software\mvp-3-card-game-backend\app\service\player_service.py", line 94, in update_wallet
    Player.id == form.id).first()
                 ^^^^^^^
AttributeError: 'UpdateWalletForm' object has no attribute 'id'
